2024-02-27 14:00:27,534 - [ERROR] - aiogram.event - (dispatcher.py)._process_update(315) - Cause exception while process update id=240532589 by bot id=5300290217
FileNotFoundError: [Errno 2] No such file or directory: 'users_files/434947488/file_5.jpg'
Traceback (most recent call last):
  File "c:\Users\RU20046792\Projects\Bot_sc_AIO3\.venv\lib\site-packages\aiogram\dispatcher\dispatcher.py", line 309, in _process_update
    response = await self.feed_update(bot, update, **kwargs)
  File "c:\Users\RU20046792\Projects\Bot_sc_AIO3\.venv\lib\site-packages\aiogram\dispatcher\dispatcher.py", line 158, in feed_update
    response = await self.update.wrap_outer_middleware(
  File "c:\Users\RU20046792\Projects\Bot_sc_AIO3\.venv\lib\site-packages\aiogram\dispatcher\middlewares\error.py", line 25, in __call__
    return await handler(event, data)
  File "c:\Users\RU20046792\Projects\Bot_sc_AIO3\.venv\lib\site-packages\aiogram\dispatcher\middlewares\user_context.py", line 27, in __call__
    return await handler(event, data)
  File "c:\Users\RU20046792\Projects\Bot_sc_AIO3\.venv\lib\site-packages\aiogram\fsm\middleware.py", line 41, in __call__
    return await handler(event, data)
  File "c:\Users\RU20046792\Projects\Bot_sc_AIO3\.venv\lib\site-packages\aiogram\dispatcher\event\telegram.py", line 121, in trigger
    return await wrapped_inner(event, kwargs)
  File "c:\Users\RU20046792\Projects\Bot_sc_AIO3\.venv\lib\site-packages\aiogram\dispatcher\event\handler.py", line 43, in call
    return await wrapped()
  File "c:\Users\RU20046792\Projects\Bot_sc_AIO3\.venv\lib\site-packages\aiogram\dispatcher\dispatcher.py", line 276, in _listen_update
    return await self.propagate_event(update_type=update_type, event=event, **kwargs)
  File "c:\Users\RU20046792\Projects\Bot_sc_AIO3\.venv\lib\site-packages\aiogram\dispatcher\router.py", line 128, in propagate_event
    return await observer.wrap_outer_middleware(_wrapped, event=event, data=kwargs)
  File "c:\Users\RU20046792\Projects\Bot_sc_AIO3\.venv\lib\site-packages\aiogram\dispatcher\router.py", line 123, in _wrapped
    return await self._propagate_event(
  File "c:\Users\RU20046792\Projects\Bot_sc_AIO3\.venv\lib\site-packages\aiogram\dispatcher\router.py", line 156, in _propagate_event
    response = await router.propagate_event(update_type=update_type, event=event, **kwargs)
  File "c:\Users\RU20046792\Projects\Bot_sc_AIO3\.venv\lib\site-packages\aiogram\dispatcher\router.py", line 128, in propagate_event
    return await observer.wrap_outer_middleware(_wrapped, event=event, data=kwargs)
  File "c:\Users\RU20046792\Projects\Bot_sc_AIO3\.venv\lib\site-packages\aiogram\dispatcher\router.py", line 123, in _wrapped
    return await self._propagate_event(
  File "c:\Users\RU20046792\Projects\Bot_sc_AIO3\.venv\lib\site-packages\aiogram\dispatcher\router.py", line 148, in _propagate_event
    response = await observer.trigger(event, **kwargs)
  File "c:\Users\RU20046792\Projects\Bot_sc_AIO3\.venv\lib\site-packages\aiogram\dispatcher\event\telegram.py", line 121, in trigger
    return await wrapped_inner(event, kwargs)
  File "C:\Users\RU20046792\Projects\Bot_sc_AIO3\middlewire\middlewares.py", line 31, in __call__
    result = await handler(event, data)
  File "c:\Users\RU20046792\Projects\Bot_sc_AIO3\.venv\lib\site-packages\aiogram\dispatcher\event\handler.py", line 43, in call
    return await wrapped()
  File "C:\Users\RU20046792\Projects\Bot_sc_AIO3\handlers\different_types.py", line 58, in pure_answer
    await message.bot.download(file=message.photo[-1].file_id, destination=f'{src}')
  File "c:\Users\RU20046792\Projects\Bot_sc_AIO3\.venv\lib\site-packages\aiogram\client\bot.py", line 428, in download
    return await self.download_file(
  File "c:\Users\RU20046792\Projects\Bot_sc_AIO3\.venv\lib\site-packages\aiogram\client\bot.py", line 383, in download_file
    await self.__download_file(destination=destination, stream=stream)
  File "c:\Users\RU20046792\Projects\Bot_sc_AIO3\.venv\lib\site-packages\aiogram\client\bot.py", line 331, in __download_file
    async with aiofiles.open(destination, "wb") as f:
  File "c:\Users\RU20046792\Projects\Bot_sc_AIO3\.venv\lib\site-packages\aiofiles\base.py", line 98, in __aenter__
    self._obj = await self._coro
  File "c:\Users\RU20046792\Projects\Bot_sc_AIO3\.venv\lib\site-packages\aiofiles\threadpool\__init__.py", line 94, in _open
    f = yield from loop.run_in_executor(executor, cb)
  File "C:\Users\RU20046792\AppData\Local\Programs\Python\Python310\lib\concurrent\futures\thread.py", line 58, in run
    result = self.fn(*self.args, **self.kwargs)
FileNotFoundError: [Errno 2] No such file or directory: 'users_files/434947488/file_5.jpg'
2024-02-27 14:03:11,335 - [ERROR] - aiogram.event - (dispatcher.py)._process_update(315) - Cause exception while process update id=240532590 by bot id=5300290217
FileNotFoundError: [Errno 2] No such file or directory: 'users_files/434947488/file_5.jpg'
Traceback (most recent call last):
  File "c:\Users\RU20046792\Projects\Bot_sc_AIO3\.venv\lib\site-packages\aiogram\dispatcher\dispatcher.py", line 309, in _process_update
    response = await self.feed_update(bot, update, **kwargs)
  File "c:\Users\RU20046792\Projects\Bot_sc_AIO3\.venv\lib\site-packages\aiogram\dispatcher\dispatcher.py", line 158, in feed_update
    response = await self.update.wrap_outer_middleware(
  File "c:\Users\RU20046792\Projects\Bot_sc_AIO3\.venv\lib\site-packages\aiogram\dispatcher\middlewares\error.py", line 25, in __call__
    return await handler(event, data)
  File "c:\Users\RU20046792\Projects\Bot_sc_AIO3\.venv\lib\site-packages\aiogram\dispatcher\middlewares\user_context.py", line 27, in __call__
    return await handler(event, data)
  File "c:\Users\RU20046792\Projects\Bot_sc_AIO3\.venv\lib\site-packages\aiogram\fsm\middleware.py", line 41, in __call__
    return await handler(event, data)
  File "c:\Users\RU20046792\Projects\Bot_sc_AIO3\.venv\lib\site-packages\aiogram\dispatcher\event\telegram.py", line 121, in trigger
    return await wrapped_inner(event, kwargs)
  File "c:\Users\RU20046792\Projects\Bot_sc_AIO3\.venv\lib\site-packages\aiogram\dispatcher\event\handler.py", line 43, in call
    return await wrapped()
  File "c:\Users\RU20046792\Projects\Bot_sc_AIO3\.venv\lib\site-packages\aiogram\dispatcher\dispatcher.py", line 276, in _listen_update
    return await self.propagate_event(update_type=update_type, event=event, **kwargs)
  File "c:\Users\RU20046792\Projects\Bot_sc_AIO3\.venv\lib\site-packages\aiogram\dispatcher\router.py", line 128, in propagate_event
    return await observer.wrap_outer_middleware(_wrapped, event=event, data=kwargs)
  File "c:\Users\RU20046792\Projects\Bot_sc_AIO3\.venv\lib\site-packages\aiogram\dispatcher\router.py", line 123, in _wrapped
    return await self._propagate_event(
  File "c:\Users\RU20046792\Projects\Bot_sc_AIO3\.venv\lib\site-packages\aiogram\dispatcher\router.py", line 156, in _propagate_event
    response = await router.propagate_event(update_type=update_type, event=event, **kwargs)
  File "c:\Users\RU20046792\Projects\Bot_sc_AIO3\.venv\lib\site-packages\aiogram\dispatcher\router.py", line 128, in propagate_event
    return await observer.wrap_outer_middleware(_wrapped, event=event, data=kwargs)
  File "c:\Users\RU20046792\Projects\Bot_sc_AIO3\.venv\lib\site-packages\aiogram\dispatcher\router.py", line 123, in _wrapped
    return await self._propagate_event(
  File "c:\Users\RU20046792\Projects\Bot_sc_AIO3\.venv\lib\site-packages\aiogram\dispatcher\router.py", line 148, in _propagate_event
    response = await observer.trigger(event, **kwargs)
  File "c:\Users\RU20046792\Projects\Bot_sc_AIO3\.venv\lib\site-packages\aiogram\dispatcher\event\telegram.py", line 121, in trigger
    return await wrapped_inner(event, kwargs)
  File "C:\Users\RU20046792\Projects\Bot_sc_AIO3\middlewire\middlewares.py", line 31, in __call__
    result = await handler(event, data)
  File "c:\Users\RU20046792\Projects\Bot_sc_AIO3\.venv\lib\site-packages\aiogram\dispatcher\event\handler.py", line 43, in call
    return await wrapped()
  File "C:\Users\RU20046792\Projects\Bot_sc_AIO3\handlers\different_types.py", line 58, in pure_answer
    await message.bot.download(file=message.photo[-1].file_id, destination=f'{src}')
  File "c:\Users\RU20046792\Projects\Bot_sc_AIO3\.venv\lib\site-packages\aiogram\client\bot.py", line 428, in download
    return await self.download_file(
  File "c:\Users\RU20046792\Projects\Bot_sc_AIO3\.venv\lib\site-packages\aiogram\client\bot.py", line 383, in download_file
    await self.__download_file(destination=destination, stream=stream)
  File "c:\Users\RU20046792\Projects\Bot_sc_AIO3\.venv\lib\site-packages\aiogram\client\bot.py", line 331, in __download_file
    async with aiofiles.open(destination, "wb") as f:
  File "c:\Users\RU20046792\Projects\Bot_sc_AIO3\.venv\lib\site-packages\aiofiles\base.py", line 98, in __aenter__
    self._obj = await self._coro
  File "c:\Users\RU20046792\Projects\Bot_sc_AIO3\.venv\lib\site-packages\aiofiles\threadpool\__init__.py", line 94, in _open
    f = yield from loop.run_in_executor(executor, cb)
  File "C:\Users\RU20046792\AppData\Local\Programs\Python\Python310\lib\concurrent\futures\thread.py", line 58, in run
    result = self.fn(*self.args, **self.kwargs)
FileNotFoundError: [Errno 2] No such file or directory: 'users_files/434947488/file_5.jpg'
2024-02-27 14:03:48,374 - [ERROR] - aiogram.event - (dispatcher.py)._process_update(315) - Cause exception while process update id=240532592 by bot id=5300290217
IndexError: list index out of range
Traceback (most recent call last):
  File "c:\Users\RU20046792\Projects\Bot_sc_AIO3\.venv\lib\site-packages\aiogram\dispatcher\dispatcher.py", line 309, in _process_update
    response = await self.feed_update(bot, update, **kwargs)
  File "c:\Users\RU20046792\Projects\Bot_sc_AIO3\.venv\lib\site-packages\aiogram\dispatcher\dispatcher.py", line 158, in feed_update
    response = await self.update.wrap_outer_middleware(
  File "c:\Users\RU20046792\Projects\Bot_sc_AIO3\.venv\lib\site-packages\aiogram\dispatcher\middlewares\error.py", line 25, in __call__
    return await handler(event, data)
  File "c:\Users\RU20046792\Projects\Bot_sc_AIO3\.venv\lib\site-packages\aiogram\dispatcher\middlewares\user_context.py", line 27, in __call__
    return await handler(event, data)
  File "c:\Users\RU20046792\Projects\Bot_sc_AIO3\.venv\lib\site-packages\aiogram\fsm\middleware.py", line 41, in __call__
    return await handler(event, data)
  File "c:\Users\RU20046792\Projects\Bot_sc_AIO3\.venv\lib\site-packages\aiogram\dispatcher\event\telegram.py", line 121, in trigger
    return await wrapped_inner(event, kwargs)
  File "c:\Users\RU20046792\Projects\Bot_sc_AIO3\.venv\lib\site-packages\aiogram\dispatcher\event\handler.py", line 43, in call
    return await wrapped()
  File "c:\Users\RU20046792\Projects\Bot_sc_AIO3\.venv\lib\site-packages\aiogram\dispatcher\dispatcher.py", line 276, in _listen_update
    return await self.propagate_event(update_type=update_type, event=event, **kwargs)
  File "c:\Users\RU20046792\Projects\Bot_sc_AIO3\.venv\lib\site-packages\aiogram\dispatcher\router.py", line 128, in propagate_event
    return await observer.wrap_outer_middleware(_wrapped, event=event, data=kwargs)
  File "c:\Users\RU20046792\Projects\Bot_sc_AIO3\.venv\lib\site-packages\aiogram\dispatcher\router.py", line 123, in _wrapped
    return await self._propagate_event(
  File "c:\Users\RU20046792\Projects\Bot_sc_AIO3\.venv\lib\site-packages\aiogram\dispatcher\router.py", line 156, in _propagate_event
    response = await router.propagate_event(update_type=update_type, event=event, **kwargs)
  File "c:\Users\RU20046792\Projects\Bot_sc_AIO3\.venv\lib\site-packages\aiogram\dispatcher\router.py", line 128, in propagate_event
    return await observer.wrap_outer_middleware(_wrapped, event=event, data=kwargs)
  File "c:\Users\RU20046792\Projects\Bot_sc_AIO3\.venv\lib\site-packages\aiogram\dispatcher\router.py", line 123, in _wrapped
    return await self._propagate_event(
  File "c:\Users\RU20046792\Projects\Bot_sc_AIO3\.venv\lib\site-packages\aiogram\dispatcher\router.py", line 148, in _propagate_event
    response = await observer.trigger(event, **kwargs)
  File "c:\Users\RU20046792\Projects\Bot_sc_AIO3\.venv\lib\site-packages\aiogram\dispatcher\event\telegram.py", line 121, in trigger
    return await wrapped_inner(event, kwargs)
  File "C:\Users\RU20046792\Projects\Bot_sc_AIO3\middlewire\middlewares.py", line 31, in __call__
    result = await handler(event, data)
  File "c:\Users\RU20046792\Projects\Bot_sc_AIO3\.venv\lib\site-packages\aiogram\dispatcher\event\handler.py", line 43, in call
    return await wrapped()
  File "C:\Users\RU20046792\Projects\Bot_sc_AIO3\handlers\different_types.py", line 68, in pure_answer
    f_logging(message.chat.id,answ[1],answ[6])
IndexError: list index out of range
